#include "thread/ThreadPool.h"
#include <assert.h>
#include <exception>
#include "thread/Thread.h"
#include "base/Exception.h"
NAMESPACE_ZL_THREAD_START

ThreadPool::ThreadPool(const std::string& name/* = "ThreadPool"*/)
    : name_(name), running_(false)
{
}

ThreadPool::~ThreadPool()
{
    if (running_)
    {
        stop();
    }
}

void ThreadPool::start(int numThreads)
{
    if (running_)
        return;
    running_ = true;
    assert(threads_.empty());
    threads_.reserve(numThreads);
    for (int i = 0; i < numThreads; ++i)
    {
        char id[32];
        ZL_SNPRINTF(id, sizeof id, "%d", i);
        threads_.push_back(new Thread(std::bind(&ThreadPool::executeThread, this), name_ + id));
    }
}

void ThreadPool::stop()
{
    running_ = false;
    queue_.stop();
    for_each(threads_.begin(), threads_.end(), std::bind(&Thread::join, std::placeholders::_1));
}

void ThreadPool::run(const Task& task)
{
    if (threads_.empty())
    {
        task();
    }
    else
    {
        queue_.push(task);
    }
}

void ThreadPool::executeThread()
{
    try
    {
        while (running_)
        {
            Task task(queue_.pop());
            if (task)
            {
                /*bool ret = */task();
            }
        }
    }
    catch (const zl::base::Exception& ex)
    {
        fprintf(stderr, "exception caught in ThreadPool %s\n", name_.c_str());
        fprintf(stderr, "reason: %s\n", ex.what());
        fprintf(stderr, "stack trace: %s\n", ex.stackTrace());
        std::abort();
    }
    catch (const std::exception& ex)
    {
        fprintf(stderr, "exception caught in ThreadPool %s\n", name_.c_str());
        fprintf(stderr, "reason: %s\n", ex.what());
        std::abort();           
    }
    catch (...)
    {
        fprintf(stderr, "unknown exception caught in ThreadPool %s\n", name_.c_str());
        throw; // rethrow
    }
}

NAMESPACE_ZL_THREAD_END
